Workbook

Sheet DATOS
D5: AMABILIDAD DEL PERSONAL | E5: RAPIDEZ DEL SERVICIO | F5: CALIDAD DE LA COMIDA | G5: VARIEDAD DEL MENU | H5: AMBIENTE ACOGEDOR | I5: AREA | M5: NOMBRE DEL SOCIO | N5: QUIEN LO ATENDIÓ | O5: AMABILIDAD DEL PERSONAL | P5: RAPIDEZ DEL SERVICIO | Q5: CALIDAD DE LA COMIDA | R5: VARIEDAD DEL MENU | S5: AMBIENTE ACOGEDOR | T5: AREA | U5: FECHA | V5: COMENTARIOS Y SUGERENCIAS
L6: 1
L7: 2
L8: 3
L9: 4
L10: 5
L11: 6
L12: 7
L13: 8
L14: 9
L15: 10
L16: 11
L17: 12
L19: 1 | M19: Belisario Pinto | N19: Daniel Leon | O19: 5 | P19: 5 | Q19: 5 | R19: 5 | S19: 5 | T19: RA | U19: 45358
L20: 2 | M20: Rubén muños | N20: Kennedy cantos | O20: 5 | P20: 4 | Q20: 4 | R20: 4 | S20: 5 | T20: RA | U20: 45358 | V20: REVISAR PLATO VOlcaN, MARISCOS SOBRECOCINADOS
L21: 3 | M21: Maria Torres de Rivadeneria | N21: Eduardo León | O21: 5 | P21: 5 | Q21: 5 | R21: 5 | S21: 5 | T21: RA | U21: 45358
L22: 4 | M22: Marcia Villavicencio Loor | N22: Eduardo León | O22: 5 | P22: 5 | Q22: 5 | R22: 5 | S22: 5 | T22: RA | U22: 45358 | V22: muy bueno todo
L23: 5 | M23: Patricia Andrade Andrade | N23: Eduardo León | O23: 5 | P23: 3 | Q23: 4 | R23: 3 | S23: 5 | T23: RA | U23: 45358 | V23: poner mejores platos en la carta
L24: 6
L25: 7
L26: 8
L27: 9
L28: 10
L29: 11
L30: 12
L31: 13
L32: 14
L33: 15
L35: 1 | M35: Pedro Solines | N35: Ambar Mite | O35: 5 | P35: 5 | Q35: 5 | R35: 5 | S35: 5 | T35: RT | U35: 45353
L36: 2 | M36: José Delgado Casanova | N36: Marlon Pilay | O36: 4 | P36: 4 | Q36: 4 | R36: 4 | S36: 4 | T36: RT | U36: 45353
L37: 3 | M37: Jorge Pazmiño | N37: Raúl Cifuentes | O37: 5 | P37: 5 | Q37: 4 | R37: 4 | S37: 4 | T37: RT | U37: 45353
L38: 4 | M38: Carlos Vascones Flor | N38: Raúl Cifuentes | O38: 5 | P38: 5 | Q38: 4 | R38: 3 | S38: 4 | T38: RT | U38: 45353
L39: 5 | M39: Rafael Avellán Huerta | N39: Erick Jiménez | O39: 5 | P39: 5 | Q39: 5 | R39: 5 | S39: 5 | T39: RT | U39: 45353
L40: 6 | M40: Joanna Lovo Garces | N40: Ámbar Mite | O40: 5 | P40: 5 | Q40: 5 | R40: 5 | S40: 5 | T40: RT | U40: 45354
L41: 7 | M41: Rafael Martínez Mori | N41: Ámbar Mite | O41: 5 | P41: 5 | Q41: 5 | R41: 5 | S41: 5 | T41: RT | U41: 45354
L42: 8 | M42: Ernesto Guzman Quiñones | N42: Ámbar Mite | O42: 5 | P42: 5 | Q42: 5 | R42: 5 | S42: 5 | T42: RT | U42: 45354
L43: 9 | M43: Erazo Muñoz armando | O43: 5 | P43: 5 | Q43: 5 | R43: 4 | S43: 5 | T43: RT | U43: 45354
L44: 10 | M44: queirolo anda María | O44: 5 | P44: 4 | Q44: 4 | R44: 4 | S44: 3 | T44: RT | U44: 45354
L45: 11 | M45: Larrea idrovo Mónica | O45: 5 | P45: 5 | Q45: 5 | R45: 4 | S45: 5 | T45: RT | U45: 45354
L46: 12 | M46: manosalvas Velasco Ricardo | O46: 5 | P46: 5 | Q46: 5 | R46: 5 | S46: 5 | T46: RT | U46: 45354
...

Sheet ANEXO
H3: BP | S3: RA | AV3: RT
D4: Nombre del socio | E4: Quien lo atendió | F4: AMABILIDAD DEL PERSONAL | G4: RAPIDEZ DEL SERVICIO | H4: CALIDAD DE LA COMIDA | I4: VARIEDAD DEL MENU | J4: AMBIENTE ACOGEDOR | K4: AREA | L4: FECHA | O4: Nombre del socio | P4: Quien lo atendió | Q4: AMABILIDAD DEL PERSONAL | R4: RAPIDEZ DEL SERVICIO | S4: CALIDAD DE LA COMIDA | T4: VARIEDAD DEL MENU | U4: AMBIENTE ACOGEDOR | V4: AREA | W4: FECHA | Z4: AMABILIDAD DEL PERSONAL | AA4: RAPIDEZ DEL SERVICIO | AB4: CALIDAD DE LA COMIDA | AC4: VARIEDAD DEL MENU | AD4: AMBIENTE ACOGEDOR | AE4: AREA | AF4: FECHA | AR4: Nombre del socio | AS4: Quien lo atendió | AT4: AMABILIDAD DEL PERSONAL | AU4: RAPIDEZ DEL SERVICIO | AV4: CALIDAD DE LA COMIDA | AW4: VARIEDAD DEL MENU | AX4: AMBIENTE ACOGEDOR | AY4: AREA | AZ4: FECHA
C5: 1 | F5: 0 | G5: 0 | H5: 0 | I5: 0 | J5: 0 | K5: BP | N5: 1 | O5: Belisario Pinto | P5: Daniel Leon | Q5: 5 | R5: 5 | S5: 5 | T5: 5 | U5: 5 | V5: RA | W5: 45323 | AQ5: 1 | AR5: Pedro Solines | AS5: Ambar Mite | AT5: 5 | AU5: 5 | AV5: 5 | AW5: 5 | AX5: 5 | AY5: RT | AZ5: 45353
C6: 2 | K6: BP | N6: 2 | O6: Rubén muños | P6: Kennedy cantos | Q6: 5 | R6: 4 | S6: 4 | T6: 4 | U6: 5 | V6: RA | W6: 45323 | AQ6: 2 | AR6: José Delgado Casanova | AS6: Marlon Pilay | AT6: 4 | AU6: 4 | AV6: 4 | AW6: 4 | AX6: 4 | AY6: RT | AZ6: 45353
C7: 3 | K7: BP | N7: 3 | O7: Maria Torres de Rivadeneria | P7: Eduardo León | Q7: 5 | R7: 5 | S7: 5 | T7: 5 | U7: 5 | V7: RA | W7: 45323 | AQ7: 3 | AR7: Jorge Pazmiño | AS7: Raúl Cifuentes | AT7: 5 | AU7: 5 | AV7: 4 | AW7: 4 | AX7: 4 | AY7: RT | AZ7: 45353
C8: 4 | K8: BP | N8: 4 | O8: Marcia Villavicencio Loor | P8: Eduardo León | Q8: 5 | R8: 5 | S8: 5 | T8: 5 | U8: 5 | V8: RA | W8: 45323 | AQ8: 4 | AR8: Carlos Vascones Flor | AS8: Raúl Cifuentes | AT8: 5 | AU8: 5 | AV8: 4 | AW8: 3 | AX8: 4 | AY8: RT | AZ8: 45353
C9: 5 | K9: BP | N9: 5 | O9: Patricia Andrade Andrade | P9: Eduardo León | Q9: 5 | R9: 3 | S9: 4 | T9: 3 | U9: 5 | V9: RA | W9: 45323 | AQ9: 5 | AR9: Rafael Avellán Huerta | AS9: Erick Jiménez | AT9: 5 | AU9: 5 | AV9: 5 | AW9: 5 | AX9: 5 | AY9: RT | AZ9: 45353
C10: 6 | K10: BP | N10: 6 | AQ10: 6 | AR10: Joanna Lovo Garces | AS10: Ámbar Mite | AT10: 5 | AU10: 5 | AV10: 5 | AW10: 5 | AX10: 5 | AY10: RT | AZ10: 45354
C11: 7 | K11: BP | N11: 7 | AQ11: 7 | AR11: Rafael Martínez Mori | AS11: Ámbar Mite | AT11: 5 | AU11: 5 | AV11: 5 | AW11: 5 | AX11: 5 | AY11: RT | AZ11: 45354
C12: 8 | K12: BP | N12: 8 | AQ12: 8 | AR12: Ernesto Guzman Quiñones | AS12: Ámbar Mite | AT12: 5 | AU12: 5 | AV12: 5 | AW12: 5 | AX12: 5 | AY12: RT | AZ12: 45354
C13: 9 | K13: BP | N13: 9 | AQ13: 9 | AR13: Erazo Muñoz armando | AT13: 5 | AU13: 5 | AV13: 5 | AW13: 4 | AX13: 5 | AY13: RT | AZ13: 45354
C14: 10 | K14: BP | N14: 10 | AQ14: 10 | AR14: queirolo anda María | AT14: 5 | AU14: 4 | AV14: 4 | AW14: 4 | AX14: 3 | AY14: RT | AZ14: 45354
C15: 11 | K15: BP | N15: 11 | AQ15: 11 | AR15: Larrea idrovo Mónica | AT15: 5 | AU15: 5 | AV15: 5 | AW15: 4 | AX15: 5 | AY15: RT | AZ15: 45354
C16: 12 | K16: BP | N16: 12 | AQ16: 12 | AR16: manosalvas Velasco Ricardo | AT16: 5 | AU16: 5 | AV16: 5 | AW16: 5 | AX16: 5 | AY16: RT | AZ16: 45354
C17: 13 | K17: BP | N17: 13 | AQ17: 13 | AR17: quintana Valdez gonzalo | AT17: 5 | AU17: 5 | AV17: 5 | AW17: 5 | AX17: 5 | AY17: RT | AZ17: 45354
C18: 14 | K18: BP | N18: 14 | AQ18: 14 | AR18: Martínez Rafael | AS18: Marlon | AT18: 5 | AU18: 5 | AV18: 5 | AW18: 5 | AX18: 5 | AY18: RT | AZ18: 45354
C19: 15 | K19: BP | N19: 15 | AQ19: 15 | AR19: Chiriboga Alban | AS19: Marlon | AT19: 5 | AU19: 5 | AV19: 5 | AW19: 5 | AX19: 5 | AY19: RT | AZ19: 45354
C20: 16 | K20: BP | N20: 16 | AQ20: 16 | AR20: Elizabeth Bohorquez | AS20: Allison Lopez | AT20: 5 | AU20: 5 | AV20: 4 | AW20: 5 | AX20: 5 | AY20: RT | AZ20: 45355
C21: 17 | K21: BP | N21: 17 | AQ21: 17 | AR21: Elizabeth Bohorquez | AS21: Allison Lopez | AT21: 5 | AU21: 5 | AV21: 4 | AW21: 5 | AX21: 5 | AY21: RT | AZ21: 45355
C22: 18 | K22: BP | N22: 18 | AQ22: 18 | AR22: Francisco Avegno | AS22: Alice | AT22: 5 | AU22: 5 | AV22: 4 | AW22: 4 | AX22: 5 | AY22: RT | AZ22: 45355
C23: 19 | K23: BP | N23: 19 | AQ23: 19 | AR23: Rosanna Plaza | AS23: Marco Yaguachi | AT23: 5 | AU23: 5 | AV23: 5 | AW23: 5 | AX23: 5 | AY23: RT | AZ23: 45356
C24: 20 | K24: BP | N24: 20 | AQ24: 20 | AR24: felipe pezo | AS24: allison | AT24: 5 | AU24: 5 | AV24: 5 | AW24: 5 | AX24: 5 | AY24: RT | AZ24: 45356
C25: 21 | K25: BP | N25: 21 | AQ25: 21 | AR25: Orlando Rodríguez | AS25: Marlon Vinces | AT25: 5 | AU25: 5 | AV25: 5 | AW25: 5 | AX25: 5 | AY25: RT | AZ25: 45356
C26: 22 | K26: BP | N26: 22 | AQ26: 22 | AR26: Edgar Lama | AS26: Marlon Vinces | AT26: 5 | AU26: 5 | AV26: 5 | AW26: 5 | AX26: 5 | AY26: RT | AZ26: 45356
C27: 23 | K27: BP | N27: 23 | AQ27: 23 | AR27: Douglas Macklif | AS27: Marco Yaguachi | AT27: 5 | AU27: 5 | AV27: 4 | AW27: 4 | AX27: 4 | AY27: RT | AZ27: 45356
C28: 24 | K28: BP | N28: 24 | AQ28: 24 | AR28: María Ycaza | AS28: Alison | AT28: 5 | AU28: 4 | AV28: 5 | AW28: 4 | AX28: 4 | AY28: RT | AZ28: 45356
C29: 25 | K29: BP | N29: 25 | AQ29: 25 | AR29: Rubén Estrella iñiga | AS29: Marco Yaguachi | AT29: 5 | AU29: 5 | AV29: 4 | AW29: 4 | AX29: 4 | AY29: RT | AZ29: 45356
... C35: 31 | K35: BP | N35: 31 | AQ35: 31 | AR35: Pedro cedeño | AS35: Erick Jiménez | AT35: 4 | AU35: 5 | AV35: 4 | AW35: 5 | AX35: 5 | AY35: RT | AZ35: 45359
C36: 32 | K36: BP | N36: 32 | AQ36: 32 | AR36: Jorge pazmiño | AT36: 5 | AU36: 5 | AV36: 5 | AW36: 5 | AX36: 5 | AY36: RT | AZ36: 45361
C37: 33 | K37: BP | N37: 33 | AQ37: 33 | AR37: Jorge pazmiño | AT37: 5 | AU37: 5 | AV37: 5 | AW37: 5 | AX37: 5 | AY37: RT | AZ37: 45361
C38: 34 | K38: BP | N38: 34 | AQ38: 34 | AR38: Gustavo Ulloa | AT38: 5 | AU38: 5 | AV38: 5 | AW38: 5 | AX38: 5 | AY38: RT | AZ38: 45361
C39: 35 | K39: BP | N39: 35 | AQ39: 35 | AR39: Julian Barragán | AS39: Erick Jiménez | AT39: 5 | AU39: 5 | AV39: 5 | AW39: 5 | AX39: 5 | AY39: RT | AZ39: 45361
C40: 36 | K40: BP | N40: 36 | AQ40: 36 | AR40: Pilar Gonzales | AS40: Raúl Cifuentes | AT40: 5 | AU40: 5 | AV40: 5 | AW40: 4 | AX40: 5 | AY40: RT | AZ40: 45361
C41: 37 | K41: BP | N41: 37 | AQ41: 37 | AR41: Delia Farah | AS41: Marlon Pilay | AT41: 5 | AU41: 5 | AV41: 5 | AW41: 5 | AX41: 5 | AY41: RT | AZ41: 45361
C42: 38 | K42: BP | N42: 38 | AQ42: 38 | AR42: Katerine Morán | AS42: Richard Pesantes | AT42: 5 | AU42: 5 | AV42: 5 | AW42: 5 | AX42: 5 | AY42: RT | AZ42: 45361
C43: 39 | K43: BP | N43: 39 | AQ43: 39 | AR43: hans shuback | AS43: Erick Jiménez | AT43: 5 | AU43: 5 | AV43: 5 | AW43: 5 | AX43: 5 | AY43: RT | AZ43: 45361
C44: 40 | K44: BP | N44: 40 | AQ44: 40 | AR44: Fernando coronel | AS44: Erick Jiménez | AT44: 5 | AU44: 5 | AV44: 5 | AW44: 4 | AX44: 5 | AY44: RT | AZ44: 45361
C45: 41 | K45: BP | N45: 41 | AQ45: 41 | AR45: María robalino | AS45: erick Jiménez | AT45: 4 | AU45: 5 | AV45: 5 | AW45: 5 | AX45: 5 | AY45: RT | AZ45: 45361
C46: 42 | K46: BP | N46: 42 | AQ46: 42 | AR46: Alfredo avila | AS46: Erick Jiménez | AT46: 5 | AU46: 5 | AV46: 5 | AW46: 5 | AX46: 5 | AY46: RT | AZ46: 45361
C47: 43 | K47: BP | N47: 43 | AQ47: 43 | AR47: Omar Serrano | AS47: Allison y Ambar | AT47: 5 | AU47: 5 | AV47: 5 | AW47: 5 | AX47: 5 | AY47: RT | AZ47: 45362
...

Sheet INDICADORES
B1: SISTEMA DE MANEJO DE INDICADORES
B3: Área/Departamento: GESTIÓN DE CALIDAD | E3: Fecha período analizado: | F3: MARZO 2024
B4: Frecuencia de Impresión : MENSUAL | E4: Fecha de elaboración: | F4: 45383
B7: INDICADORES | C7: Unidad | D7: Mínimo | E7: Objetivo | F7: PROMEDIO
G9: ..
B11: Satisfacción del socio en cuanto a la Amabilidad personal en BP | C11: # | D11: 0.9 | E11: 1 | F11: =ANEXO!F749 -> 0
B12: Satisfacción del Socio en cuanto a la Rapidez del servicio BP | C12: # | D12: 0.9 | E12: 1 | F12: =ANEXO!G749 -> 0
B13: Satisfacción del Socio en cuanto a la Calidad de la Comida BP | C13: # | D13: 0.9 | E13: 1 | F13: =ANEXO!H749 -> 0
B14: Satisfacción del Socio en cuanto a la variedad del menú BP | C14: # | D14: 0.9 | E14: 1 | F14: =ANEXO!I749 -> 0
B15: Satisfacción del Socio en cuanto al Ambiente Acogedor BP | C15: # | D15: 0.9 | E15: 1 | F15: =ANEXO!J749 -> 0
B16: Satisfacción del socio en cuanto a la Amabilidad personal en Aqua | C16: # | D16: 0.9 | E16: 1 | F16: =ANEXO!Q$749 -> 1
B17: Satisfacción del Socio en cuanto a la Rapidez del servicio Aqua | C17: # | D17: 0.9 | E17: 1 | F17: =ANEXO!R749 -> 0.88
B18: Satisfacción del Socio en cuanto a la Calidad de la Comida Aqua | C18: # | D18: 0.9 | E18: 1 | F18: =ANEXO!S749 -> 0.92
B19: Satisfacción del Socio en cuanto a la variedad del menú Aqua | C19: # | D19: 0.9 | E19: 1 | F19: =ANEXO!T749 -> 0.88
B20: Satisfacción del Socio en cuanto al Ambiente Acogedor Aqua | C20: # | D20: 0.9 | E20: 1 | F20: =ANEXO!U749 -> 1
B21: Satisfacción del socio en cuanto a la Amabilidad del personal en TT | C21: # | D21: 0.9 | E21: 1
B22: Satisfacción del Socio en cuanto a la Rapidez del servicio TT | C22: # | D22: 0.9 | E22: 1
B23: Satisfacción del Socio en cuanto a la Calidad de la Comida TT | C23: # | D23: 0.9 | E23: 1
B24: Satisfacción del Socio en cuanto a la variedad del menú TT | C24: # | D24: 0.9 | E24: 1
B25: Satisfacción del Socio en cuanto al Ambiente Acogedor TT | C25: # | D25: 0.9 | E25: 1
B26: Amabilidad del personal Restaurante Rooftop | C26: # | D26: 0.9 | E26: 1 | F26: =ANEXO!AT749 -> 0.99215686
B27: Rapidez del servicio Restaurante Rooftop | C27: # | D27: 0.9 | E27: 1 | F27: =ANEXO!AU749 -> 0.99019608
B28: Calidad de la Comida Restaurante Rooftop | C28: # | D28: 0.9 | E28: 1 | F28: =ANEXO!AV749 -> 0.9627451
B29: Variedad del menú Restaurante Rooftop | C29: # | D29: 0.9 | E29: 1 | F29: =ANEXO!AW749 -> 0.95882353
B30: Ambiente Acogedor Restaurante Rooftop | C30: # | D30: 0.9 | E30: 1 | F30: =ANEXO!AX749 -> 0.97058824
B33: Amabilidad del personal | C33: # | D33: 0.9 | E33: 1 | F33: =(F16+F21+F26)/2 -> 0.99607843
B34: Rapidez del servicio | C34: # | D34: 0.9 | E34: 1 | F34: =(F12+F17+F22+F27)/2 -> 0.93509804
B35: Calidad de la Comida | C35: # | D35: 0.9 | E35: 1 | F35: =(F13+F18+F23+F28)/2 -> 0.94137255
B36: Variedad del menu | C36: # | D36: 0.9 | E36: 1 | F36: =(F14+F19+F24+F29)/2 -> 0.91941176
B37: Ambiente Acogedor | C37: # | D37: 0.9 | E37: 1 | F37: =(F15+F20+F25+F30)/2 -> 0.98529412
F38: =AVERAGE(F33:F37) -> 0.95545098
