Workbook

Sheet DATOS
D5: AMABILIDAD DEL PERSONAL | E5: RAPIDEZ DEL SERVICIO | F5: CALIDAD DE LA COMIDA | G5: VARIEDAD DEL MENU | H5: AMBIENTE ACOGEDOR | I5: AREA | M5: Nombre del socio | N5: Quien lo atendió | O5: AMABILIDAD DEL PERSONAL | P5: RAPIDEZ DEL SERVICIO | Q5: CALIDAD DE LA COMIDA | R5: VARIEDAD DEL MENU | S5: AMBIENTE ACOGEDOR | T5: AREA | U5: FECHA | V5: COMENTARIOS Y SUGERENCIAS
L6: 1 | M6: Mario proaño | N6: luis saltos | O6: 5 | P6: 5 | Q6: 5 | R6: 5 | S6: 5 | T6: BP | U6: 45415
L7: 2 | M7: Mario proaño | N7: luis saltos | O7: 5 | P7: 5 | Q7: 5 | R7: 5 | S7: 5 | T7: BP | U7: 45415
L8: 3 | M8: liviere moreno | N8: Efraín campoverde | O8: 5 | P8: 5 | Q8: 5 | R8: 5 | S8: 5 | T8: BP | U8: 45415
L9: 4 | M9: Claudia Mendoza | N9: Efraín Campoverde | O9: 5 | P9: 5 | Q9: 5 | R9: 5 | S9: 5 | T9: BP | U9: 45415 | V9: Todo excelente
L10: 5 | M10: Claudia Mendoza | N10: Efraín Campoverde | O10: 5 | P10: 5 | Q10: 5 | R10: 5 | S10: 5 | T10: BP | U10: 45415 | V10: Todo excelente
L11: 6 | M11: Johnny Garcia | N11: Efrén Campoverde | O11: 5 | P11: 4 | Q11: 5 | R11: 4 | S11: 4 | T11: BP | U11: 45416
L12: 7 | M12: Johnny Garcia | N12: Efrén Campoverde | O12: 5 | P12: 5 | Q12: 5 | R12: 5 | S12: 4 | T12: BP | U12: 45416
L13: 8 | M13: Sebastián Ramírez | N13: Efraín Campoverde | O13: 5 | P13: 4 | Q13: 4 | R13: 3 | S13: 5 | T13: BP | U13: 45416
L14: 9 | M14: Elly !ay Sánchez | N14: Efraín Campoverde | O14: 5 | P14: 5 | Q14: 5 | R14: 5 | S14: 5 | T14: BP | U14: 45416 | V14: todo estuvo excelente
L15: 10 | M15: Giuliana Graber | N15: Efrén Campoverde | O15: 5 | P15: 5 | Q15: 5 | R15: 5 | S15: 5 | T15: BP | U15: 45417
L16: 11 | M16: pedro zevallos Navarro | N16: Fausto | O16: 5 | P16: 5 | Q16: 5 | R16: 5 | S16: 5 | T16: BP | U16: 45417
L17: 12 | M17: pedro zevallos Navarro | N17: Fausto | O17: 5 | P17: 5 | Q17: 5 | R17: 5 | S17: 5 | T17: BP | U17: 45417
L18: 13 | M18: Freddy Rodriguez Endara | N18: Efrain | O18: 5 | P18: 5 | Q18: 5 | R18: 5 | S18: 5 | T18: BP | U18: 45417
L19: 14 | M19: Freddy Rodriguez Endara | N19: Efrain | O19: 5 | P19: 5 | Q19: 5 | R19: 5 | S19: 5 | T19: BP | U19: 45417
L20: 15 | M20: José Moscoso | N20: Segundo Rivera | O20: 5 | P20: 5 | Q20: 5 | R20: 5 | S20: 5 | T20: BP | U20: 45417
L21: 16 | M21: Jimmy salazar | N21: rivera | O21: 5 | P21: 5 | Q21: 5 | R21: 3 | S21: 5 | T21: BP | U21: 45417
L22: 17 | M22: Estefanía jacome | N22: Efraín campoverde | O22: 5 | P22: 5 | Q22: 4 | R22: 5 | S22: 5 | T22: BP | U22: 45417
L23: 18 | M23: Eduardo altamirano | N23: fausto | O23: 5 | P23: 5 | Q23: 5 | R23: 5 | S23: 5 | T23: BP | U23: 45419 | V23: muybuenmesero
L24: 19 | M24: marco Ramírez franco | N24: Susana salinas | O24: 1 | P24: 1 | Q24: 1 | R24: 1 | S24: 1 | T24: BP | U24: 45419 | V24: exelente
L25: 20 | M25: Nicolás Jungbluth | N25: Efraín Campoverde | O25: 5 | P25: 5 | Q25: 5 | R25: 5 | S25: 5 | T25: BP | U25: 45420 | V25: Todo excelente!
L26: 21 | M26: Xavier Chavarría Baquerizo | N26: Susana salinas | O26: 5 | P26: 5 | Q26: 5 | R26: 5 | S26: 5 | T26: BP | U26: 45420
L27: 22 | M27: Jose solines Aguayo | N27: Wellington | O27: 5 | P27: 4 | Q27: 5 | R27: 4 | S27: 5 | T27: BP | U27: 45428
L28: 23 | M28: Gaston León Nuques | N28: Daniel Leon | O28: 5 | P28: 5 | Q28: 5 | R28: 5 | S28: 5 | T28: BP | U28: 45428
L29: 24 | M29: Luigi Ramirez Baquero | N29: Elohim Vasquez | O29: 5 | P29: 5 | Q29: 5 | R29: 5 | S29: 5 | T29: BP | U29: 45428
L30: 25 | M30: Aquiles Guerrero | N30: Kennedy Cantos Mosquera | O30: 5 | P30: 4 | Q30: 4 | R30: 4 | S30: 4 | T30: BP | U30: 45428
L31: 26 | M31: Juan Carlos Pinchin Soriano | N31: Elohim Vásquez | O31: 5 | P31: 4 | Q31: 4 | R31: 4 | S31: 4 | T31: BP | U31: 45428
L32: 27 | M32: Javier salazar | N32: Efraín | O32: 5 | P32: 5 | Q32: 5 | R32: 5 | S32: 5 | T32: BP | U32: 45430
L33: 28 | M33: Francisco Peña | N33: Efrain | O33: 5 | P33: 5 | Q33: 5 | R33: 5 | S33: 5 | T33: BP | U33: 45430
L34: 29 | M34: Gregorio Camposano | N34: Efrain | O34: 5 | P34: 5 | Q34: 5 | R34: 5 | S34: 5 | T34: BP | U34: 45430 | V34: Bien
L35: 30 | M35: jorge | N35: Efrain | O35: 5 | P35: 5 | Q35: 5 | R35: 5 | S35: 5 | T35: BP | U35: 45430
L36: 31 | M36: José Ferretti Calderon | N36: Efrain | O36: 5 | P36: 5 | Q36: 5 | R36: 5 | S36: 5 | T36: BP | U36: 45430
L37: 32 | M37: MOISÉS SOSA | N37: EFRAIN CAMPOVERDE | O37: 5 | P37: 5 | Q37: 5 | R37: 5 | S37: 5 | T37: BP | U37: 45430
L38: 33 | M38: Allan yepez | N38: susana | O38: 5 | P38: 5 | Q38: 5 | R38: 5 | S38: 5 | T38: BP | U38: 45430
L39: 34 | M39: carlos concha | N39: Enrique | O39: 5 | P39: 5 | Q39: 5 | R39: 5 | S39: 5 | T39: BP | U39: 45434
L40: 35 | M40: Barragán medina | N40: Efraín Campoverde | O40: 5 | P40: 5 | Q40: 5 | R40: 5 | S40: 5 | T40: BP | U40: 45436
L41: 36 | M41: Verónica Plaza | N41: Efrain cAmpo ve rde | O41: 5 | P41: 5 | Q41: 5 | R41: 5 | S41: 5 | T41: BP | U41: 45436 | V41: todo bien
L42: 37 | M42: Patricia Tacury | N42: Efrain cAmpo | O42: 5 | P42: 5 | Q42: 5 | R42: 5 | S42: 5 | T42: BP | U42: 45436
L43: 38 | M43: Ab. Mario Proaño | N43: Efrain | O43: 5 | P43: 5 | Q43: 5 | R43: 5 | S43: 5 | T43: BP | U43: 45436
L44: 39 | M44: Carlo | N44: Campoverde | O44: 5 | P44: 5 | Q44: 5 | R44: 5 | S44: 5 | T44: BP | U44: 45436
...

Sheet GYE
F3: BP | O3: 1910 | AP3: RC
D4: AMABILIDAD DEL PERSONAL | E4: RAPIDEZ DEL SERVICIO | F4: CALIDAD DE LA COMIDA | G4: VARIEDAD DEL MENU | H4: AMBIENTE ACOGEDOR | I4: AREA | J4: FECHA | M4: AMABILIDAD DEL PERSONAL | N4: RAPIDEZ DEL SERVICIO | O4: CALIDAD DE LA COMIDA | P4: VARIEDAD DEL MENU | Q4: AMBIENTE ACOGEDOR | R4: AREA | S4: FECHA | V4: AMABILIDAD DEL PERSONAL | W4: RAPIDEZ DEL SERVICIO | X4: CALIDAD DE LA COMIDA | Y4: VARIEDAD DEL MENU | Z4: AMBIENTE ACOGEDOR | AA4: AREA | AB4: FECHA | AN4: AMABILIDAD DEL PERSONAL | AO4: RAPIDEZ DEL SERVICIO | AP4: CALIDAD DE LA COMIDA | AQ4: VARIEDAD DEL MENU | AR4: AMBIENTE ACOGEDOR | AS4: AREA | AT4: FECHA
C5: 1 | D5: 5 | E5: 5 | F5: 5 | G5: 5 | H5: 5 | I5: BP | J5: 45415 | L5: 1 | M5: 5 | N5: 2 | O5: 3 | P5: 3 | Q5: 4 | R5: 1910 | S5: 45413.602 | AM5: 1 | AN5: 5 | AO5: 5 | AP5: 4 | AQ5: 4 | AR5: 3 | AS5: RC | AT5: 45413.571
C6: 2 | D6: 5 | E6: 5 | F6: 5 | G6: 5 | H6: 5 | I6: BP | J6: 45415 | L6: 2 | M6: 5 | N6: 5 | O6: 5 | P6: 5 | Q6: 5 | R6: 1910 | S6: 45413.643 | AM6: 2 | AN6: 5 | AO6: 5 | AP6: 4 | AQ6: 4 | AR6: 3 | AS6: RC | AT6: 45413.572
C7: 3 | D7: 5 | E7: 5 | F7: 5 | G7: 5 | H7: 5 | I7: BP | J7: 45415 | L7: 3 | M7: 5 | N7: 5 | O7: 5 | P7: 5 | Q7: 5 | R7: 1910 | S7: 45418.621 | AM7: 3 | AN7: 5 | AO7: 5 | AP7: 5 | AQ7: 5 | AR7: 5 | AS7: RC | AT7: 45413.582
C8: 4 | D8: 5 | E8: 5 | F8: 5 | G8: 5 | H8: 5 | I8: BP | J8: 45415 | L8: 4 | M8: 5 | N8: 5 | O8: 5 | P8: 5 | Q8: 5 | R8: 1910 | S8: 45420.586 | AM8: 4 | AN8: 5 | AO8: 5 | AP8: 5 | AQ8: 5 | AR8: 5 | AS8: RC | AT8: 45413.687
C9: 5 | D9: 5 | E9: 5 | F9: 5 | G9: 5 | H9: 5 | I9: BP | J9: 45415 | L9: 5 | M9: 5 | N9: 5 | O9: 5 | P9: 5 | Q9: 5 | R9: 1910 | S9: 45420.649 | AM9: 5 | AN9: 5 | AO9: 5 | AP9: 5 | AQ9: 5 | AR9: 5 | AS9: RC | AT9: 45413.69
C10: 6 | D10: 5 | E10: 4 | F10: 5 | G10: 4 | H10: 4 | I10: BP | J10: 45416 | L10: 6 | M10: 5 | N10: 5 | O10: 5 | P10: 4 | Q10: 5 | R10: 1910 | S10: 45420.654 | AM10: 6 | AN10: 5 | AO10: 5 | AP10: 5 | AQ10: 5 | AR10: 5 | AS10: RC | AT10: 45414.616
C11: 7 | D11: 5 | E11: 5 | F11: 5 | G11: 5 | H11: 4 | I11: BP | J11: 45416 | L11: 7 | M11: 5 | N11: 5 | O11: 5 | P11: 4 | Q11: 5 | R11: 1910 | S11: 45420.654 | AM11: 7 | AN11: 5 | AO11: 5 | AP11: 5 | AQ11: 4 | AR11: 4 | AS11: RC | AT11: 45414.643
C12: 8 | D12: 5 | E12: 4 | F12: 4 | G12: 3 | H12: 5 | I12: BP | J12: 45416 | L12: 8 | M12: 5 | N12: 4 | O12: 5 | P12: 5 | Q12: 5 | R12: 1910 | S12: 45421.652 | AM12: 8 | AN12: 5 | AO12: 5 | AP12: 5 | AQ12: 5 | AR12: 5 | AS12: RC | AT12: 45415.633
C13: 9 | D13: 5 | E13: 5 | F13: 5 | G13: 5 | H13: 5 | I13: BP | J13: 45416 | L13: 9 | M13: 5 | N13: 5 | O13: 5 | P13: 5 | Q13: 3 | R13: 1910 | S13: 45422.667 | AM13: 9 | AN13: 5 | AO13: 5 | AP13: 5 | AQ13: 5 | AR13: 5 | AS13: RC | AT13: 45415.634
C14: 10 | D14: 5 | E14: 5 | F14: 5 | G14: 5 | H14: 5 | I14: BP | J14: 45417 | L14: 10 | M14: 5 | N14: 5 | O14: 5 | P14: 5 | Q14: 5 | R14: 1910 | S14: 45424.597 | AM14: 10 | AN14: 5 | AO14: 5 | AP14: 5 | AQ14: 5 | AR14: 5 | AS14: RC | AT14: 45415.643
C15: 11 | D15: 5 | E15: 5 | F15: 5 | G15: 5 | H15: 5 | I15: BP | J15: 45417 | L15: 11 | M15: 5 | N15: 5 | O15: 5 | P15: 3 | Q15: 4 | R15: 1910 | S15: 45427.588 | AM15: 11 | AN15: 5 | AO15: 5 | AP15: 5 | AQ15: 5 | AR15: 5 | AS15: RC | AT15: 45415.657
C16: 12 | D16: 5 | E16: 5 | F16: 5 | G16: 5 | H16: 5 | I16: BP | J16: 45417 | L16: 12 | M16: 5 | N16: 5 | O16: 5 | P16: 5 | Q16: 5 | R16: 1910 | S16: 45427.599 | AM16: 12 | AN16: 5 | AO16: 5 | AP16: 5 | AQ16: 5 | AR16: 5 | AS16: RC | AT16: 45416.656
C17: 13 | D17: 5 | E17: 5 | F17: 5 | G17: 5 | H17: 5 | I17: BP | J17: 45417 | L17: 13 | M17: 5 | N17: 3 | O17: 5 | P17: 4 | Q17: 5 | R17: 1910 | S17: 45433.614 | AM17: 13 | AN17: 5 | AO17: 5 | AP17: 3 | AQ17: 4 | AR17: 5 | AS17: RC | AT17: 45416.657
C18: 14 | D18: 5 | E18: 5 | F18: 5 | G18: 5 | H18: 5 | I18: BP | J18: 45417 | L18: 14 | R18: 1910 | AM18: 14 | AN18: 5 | AO18: 5 | AP18: 4 | AQ18: 4 | AR18: 4 | AS18: RC | AT18: 45416.658
C19: 15 | D19: 5 | E19: 5 | F19: 5 | G19: 5 | H19: 5 | I19: BP | J19: 45417 | L19: 15 | R19: 1910 | AM19: 15 | AN19: 5 | AO19: 5 | AP19: 5 | AQ19: 5 | AR19: 5 | AS19: RC | AT19: 45420.572
C20: 16 | D20: 5 | E20: 5 | F20: 5 | G20: 3 | H20: 5 | I20: BP | J20: 45417 | L20: 16 | R20: 1910 | AM20: 16 | AN20: 5 | AO20: 5 | AP20: 5 | AQ20: 5 | AR20: 5 | AS20: RC | AT20: 45420.607
C21: 17 | D21: 5 | E21: 5 | F21: 4 | G21: 5 | H21: 5 | I21: BP | J21: 45417 | L21: 17 | R21: 1910 | AM21: 17 | AN21: 5 | AO21: 5 | AP21: 5 | AQ21: 5 | AR21: 5 | AS21: RC | AT21: 45420.639
C22: 18 | D22: 5 | E22: 5 | F22: 5 | G22: 5 | H22: 5 | I22: BP | J22: 45419 | L22: 18 | R22: 1910 | AM22: 18 | AN22: 5 | AO22: 5 | AP22: 5 | AQ22: 5 | AR22: 5 | AS22: RC | AT22: 45420.659
C23: 19 | D23: 1 | E23: 1 | F23: 1 | G23: 1 | H23: 1 | I23: BP | J23: 45419 | L23: 19 | R23: 1910 | AM23: 19 | AN23: 5 | AO23: 5 | AP23: 5 | AQ23: 5 | AR23: 5 | AS23: RC | AT23: 45421.585
C24: 20 | D24: 5 | E24: 5 | F24: 5 | G24: 5 | H24: 5 | I24: BP | J24: 45420 | L24: 20 | R24: 1910 | AM24: 20 | AN24: 5 | AO24: 5 | AP24: 5 | AQ24: 5 | AR24: 5 | AS24: RC | AT24: 45421.585
C25: 21 | D25: 5 | E25: 5 | F25: 5 | G25: 5 | H25: 5 | I25: BP | J25: 45420 | L25: 21 | R25: 1910 | AM25: 21 | AN25: 1 | AO25: 1 | AP25: 1 | AQ25: 1 | AR25: 1 | AS25: RC | AT25: 45421.622
C26: 22 | D26: 5 | E26: 4 | F26: 5 | G26: 4 | H26: 5 | I26: BP | J26: 45428 | L26: 22 | R26: 1910 | AM26: 22 | AN26: 5 | AO26: 5 | AP26: 5 | AQ26: 5 | AR26: 5 | AS26: RC | AT26: 45421.64
C27: 23 | D27: 5 | E27: 5 | F27: 5 | G27: 5 | H27: 5 | I27: BP | J27: 45428 | L27: 23 | R27: 1910 | AM27: 23 | AN27: 5 | AO27: 5 | AP27: 5 | AQ27: 5 | AR27: 5 | AS27: RC | AT27: 45421.642
C28: 24 | D28: 5 | E28: 5 | F28: 5 | G28: 5 | H28: 5 | I28: BP | J28: 45428 | L28: 24 | R28: 1910 | AM28: 24 | AN28: 5 | AO28: 5 | AP28: 5 | AQ28: 5 | AR28: 5 | AS28: RC | AT28: 45421.651
C29: 25 | D29: 5 | E29: 4 | F29: 4 | G29: 4 | H29: 4 | I29: BP | J29: 45428 | L29: 25 | R29: 1910 | AM29: 25 | AN29: 5 | AO29: 5 | AP29: 5 | AQ29: 5 | AR29: 5 | AS29: RC | AT29: 45422.56
... C47: 43 | D47: 5 | E47: 5 | F47: 5 | G47: 5 | H47: 5 | I47: BP | J47: 45437 | L47: 43 | R47: 1910 | AM47: 43 | AN47: 5 | AO47: 5 | AP47: 3 | AQ47: 4 | AR47: 4 | AS47: RC | AT47: 45427.648
C48: 44 | I48: BP | L48: 44 | R48: 1910 | AM48: 44 | AN48: 5 | AO48: 5 | AP48: 4 | AQ48: 5 | AR48: 5 | AS48: RC | AT48: 45427.661
C49: 45 | I49: BP | L49: 45 | R49: 1910 | AM49: 45 | AN49: 5 | AO49: 5 | AP49: 4 | AQ49: 5 | AR49: 5 | AS49: RC | AT49: 45427.665
C50: 46 | I50: BP | L50: 46 | R50: 1910 | AM50: 46 | AN50: 5 | AO50: 5 | AP50: 5 | AQ50: 5 | AR50: 5 | AS50: RC | AT50: 45428.622
C51: 47 | I51: BP | L51: 47 | R51: 1910 | AM51: 47 | AN51: 5 | AO51: 5 | AP51: 5 | AQ51: 5 | AR51: 5 | AS51: RC | AT51: 45428.641
C52: 48 | I52: BP | L52: 48 | R52: 1910 | AM52: 48 | AN52: 5 | AO52: 5 | AP52: 5 | AQ52: 5 | AR52: 5 | AS52: RC | AT52: 45429.588
C53: 49 | I53: BP | L53: 49 | R53: 1910 | AM53: 49 | AN53: 5 | AO53: 5 | AP53: 5 | AQ53: 5 | AR53: 5 | AS53: RC | AT53: 45429.608
C54: 50 | I54: BP | L54: 50 | R54: 1910 | AM54: 50 | AN54: 5 | AO54: 5 | AP54: 5 | AQ54: 5 | AR54: 5 | AS54: RC | AT54: 45429.667
C55: 51 | I55: BP | L55: 51 | R55: 1910 | AM55: 51 | AN55: 5 | AO55: 5 | AP55: 5 | AQ55: 5 | AR55: 5 | AS55: RC | AT55: 45429.667
C56: 52 | I56: BP | L56: 52 | R56: 1910 | AM56: 52 | AN56: 5 | AO56: 5 | AP56: 5 | AQ56: 5 | AR56: 5 | AS56: RC | AT56: 45429.668
C57: 53 | I57: BP | L57: 53 | R57: 1910 | AM57: 53 | AN57: 5 | AO57: 5 | AP57: 5 | AQ57: 5 | AR57: 5 | AS57: RC | AT57: 45430.621
C58: 54 | I58: BP | L58: 54 | R58: 1910 | AM58: 54 | AN58: 5 | AO58: 5 | AP58: 5 | AQ58: 5 | AR58: 5 | AS58: RC | AT58: 45430.709
C59: 55 | I59: BP | L59: 55 | R59: 1910 | AM59: 55 | AN59: 5 | AO59: 5 | AP59: 5 | AQ59: 5 | AR59: 5 | AS59: RC | AT59: 45430.71
...

Sheet INDICADORES
B1: SISTEMA DE MANEJO DE INDICADORES
B3: Área/Departamento: GESTIÓN DE CALIDAD | E3: Fecha período analizado: | F3: MAYO 2024
B4: Frecuencia de Impresión : MENSUAL | E4: Fecha de elaboración: | F4: 45447
B7: INDICADORES | C7: Unidad | D7: Mínimo | E7: Objetivo | F7: PROMEDIO
G9: ..
B11: Satisfacción del socio en cuanto a la Amabilidad personal en BC/BP | C11: # | D11: 0.9 | E11: 1 | F11: =GYE!D749 -> 0.98139535
B12: Satisfacción del Socio en cuanto a la Rapidez del servicio BC/BP | C12: # | D12: 0.9 | E12: 1 | F12: =GYE!E749 -> 0.94883721
B13: Satisfacción del Socio en cuanto a la Calidad de la Comida BC/BP | C13: # | D13: 0.9 | E13: 1 | F13: =GYE!F749 -> 0.95348837
B14: Satisfacción del Socio en cuanto a la variedad del menú BC/BP | C14: # | D14: 0.9 | E14: 1 | F14: =GYE!G749 -> 0.93488372
B15: Satisfacción del Socio en cuanto al Ambiente Acogedor BC/BP | C15: # | D15: 0.9 | E15: 1 | F15: =GYE!H749 -> 0.94883721
B16: Satisfacción del socio en cuanto a la Amabilidad personal en 1910 | C16: # | D16: 0.9 | E16: 1 | F16: =GYE!M$749 -> 1
B17: Satisfacción del Socio en cuanto a la Rapidez del servicio 1910 | C17: # | D17: 0.9 | E17: 1 | F17: =GYE!N749 -> 0.90769231
B18: Satisfacción del Socio en cuanto a la Calidad de la Comida 1910 | C18: # | D18: 0.9 | E18: 1 | F18: =GYE!O749 -> 0.96923077
B19: Satisfacción del Socio en cuanto a la variedad del menú 1910 | C19: # | D19: 0.9 | E19: 1 | F19: =GYE!P749 -> 0.89230769
B20: Satisfacción del Socio en cuanto al Ambiente Acogedor 1910 | C20: # | D20: 0.9 | E20: 1 | F20: =GYE!Q749 -> 0.93846154
B21: Satisfacción del socio en cuanto a la Amabilidad del personal en TT | C21: # | D21: 0.9 | E21: 1
B22: Satisfacción del Socio en cuanto a la Rapidez del servicio TT | C22: # | D22: 0.9 | E22: 1
B23: Satisfacción del Socio en cuanto a la Calidad de la Comida TT | C23: # | D23: 0.9 | E23: 1
B24: Satisfacción del Socio en cuanto a la variedad del menú TT | C24: # | D24: 0.9 | E24: 1
B25: Satisfacción del Socio en cuanto al Ambiente Acogedor TT | C25: # | D25: 0.9 | E25: 1
B26: Amabilidad del personal Restaurante Clasico | C26: # | D26: 0.9 | E26: 1 | F26: =GYE!AN749 -> 0.98969072
B27: Rapidez del servicio Restaurante Clasico | C27: # | D27: 0.9 | E27: 1 | F27: =GYE!AO749 -> 0.97938144
B28: Calidad de la Comida Restaurante Clasico | C28: # | D28: 0.9 | E28: 1 | F28: =GYE!AP749 -> 0.94226804
B29: Variedad del menú Restaurante Clasico | C29: # | D29: 0.9 | E29: 1 | F29: =GYE!AQ749 -> 0.91752577
B30: Ambiente Acogedor Restaurante Clasico | C30: # | D30: 0.9 | E30: 1 | F30: =GYE!AR749 -> 0.95257732
B33: Amabilidad del personal | C33: # | D33: 0.9 | E33: 1 | F33: =(F11+F16+F26)/3 -> 0.99036202
B34: Rapidez del servicio | C34: # | D34: 0.9 | E34: 1 | F34: =(F12+F17+F27)/3 -> 0.94530365
B35: Calidad de la Comida | C35: # | D35: 0.9 | E35: 1 | F35: =(F13+F18+F28)/3 -> 0.95499573
B36: Variedad del menu | C36: # | D36: 0.9 | E36: 1 | F36: =(F14+F19+F29)/3 -> 0.91490573
B37: Ambiente Acogedor | C37: # | D37: 0.9 | E37: 1 | F37: =(F15+F20+F30)/3 -> 0.94662536
F38: =AVERAGE(F33:F37) -> 0.9504385
